{
    "error_message": "Graph execution error:\n\nDetected at node gradient_tape/mean_squared_error/BroadcastGradientArgs defined at (most recent call last):\n  File \"/Users/pier/Projects/neural_networks/src/main.py\", line 160, in <module>\n\n  File \"/Users/pier/Projects/neural_networks/src/main.py\", line 147, in main\n\n  File \"/Users/pier/Projects/neural_networks/src/main.py\", line 97, in process_configuration\n\n  File \"/Users/pier/Projects/neural_networks/src/deepnn/model.py\", line 132, in train_model\n\n  File \"/Users/pier/Projects/neural_networks/.venv/lib/python3.11/site-packages/keras/src/utils/traceback_utils.py\", line 65, in error_handler\n\n  File \"/Users/pier/Projects/neural_networks/.venv/lib/python3.11/site-packages/keras/src/engine/training.py\", line 1783, in fit\n\n  File \"/Users/pier/Projects/neural_networks/.venv/lib/python3.11/site-packages/keras/src/engine/training.py\", line 1377, in train_function\n\n  File \"/Users/pier/Projects/neural_networks/.venv/lib/python3.11/site-packages/keras/src/engine/training.py\", line 1360, in step_function\n\n  File \"/Users/pier/Projects/neural_networks/.venv/lib/python3.11/site-packages/keras/src/engine/training.py\", line 1349, in run_step\n\n  File \"/Users/pier/Projects/neural_networks/.venv/lib/python3.11/site-packages/keras/src/engine/training.py\", line 1130, in train_step\n\n  File \"/Users/pier/Projects/neural_networks/.venv/lib/python3.11/site-packages/keras/src/optimizers/legacy/optimizer_v2.py\", line 598, in minimize\n\n  File \"/Users/pier/Projects/neural_networks/.venv/lib/python3.11/site-packages/keras/src/optimizers/legacy/optimizer_v2.py\", line 656, in _compute_gradients\n\n  File \"/Users/pier/Projects/neural_networks/.venv/lib/python3.11/site-packages/keras/src/optimizers/legacy/optimizer_v2.py\", line 532, in _get_gradients\n\nIncompatible shapes: [64,500,3,12] vs. [64,12]\n\t [[{{node gradient_tape/mean_squared_error/BroadcastGradientArgs}}]] [Op:__inference_train_function_9080]",
    "traceback": "Traceback (most recent call last):\n  File \"/Users/pier/Projects/neural_networks/src/main.py\", line 97, in process_configuration\n    history = neural_network.train_model()\n              ^^^^^^^^^^^^^^^^^^^^^^^^^^^^\n  File \"/Users/pier/Projects/neural_networks/src/deepnn/model.py\", line 132, in train_model\n    history = self.model.fit(\n              ^^^^^^^^^^^^^^^\n  File \"/Users/pier/Projects/neural_networks/.venv/lib/python3.11/site-packages/keras/src/utils/traceback_utils.py\", line 70, in error_handler\n    raise e.with_traceback(filtered_tb) from None\n  File \"/Users/pier/Projects/neural_networks/.venv/lib/python3.11/site-packages/tensorflow/python/eager/execute.py\", line 66, in quick_execute\n    except TypeError as e:\ntensorflow.python.framework.errors_impl.InvalidArgumentError: Graph execution error:\n\nDetected at node gradient_tape/mean_squared_error/BroadcastGradientArgs defined at (most recent call last):\n  File \"/Users/pier/Projects/neural_networks/src/main.py\", line 160, in <module>\n\n  File \"/Users/pier/Projects/neural_networks/src/main.py\", line 147, in main\n\n  File \"/Users/pier/Projects/neural_networks/src/main.py\", line 97, in process_configuration\n\n  File \"/Users/pier/Projects/neural_networks/src/deepnn/model.py\", line 132, in train_model\n\n  File \"/Users/pier/Projects/neural_networks/.venv/lib/python3.11/site-packages/keras/src/utils/traceback_utils.py\", line 65, in error_handler\n\n  File \"/Users/pier/Projects/neural_networks/.venv/lib/python3.11/site-packages/keras/src/engine/training.py\", line 1783, in fit\n\n  File \"/Users/pier/Projects/neural_networks/.venv/lib/python3.11/site-packages/keras/src/engine/training.py\", line 1377, in train_function\n\n  File \"/Users/pier/Projects/neural_networks/.venv/lib/python3.11/site-packages/keras/src/engine/training.py\", line 1360, in step_function\n\n  File \"/Users/pier/Projects/neural_networks/.venv/lib/python3.11/site-packages/keras/src/engine/training.py\", line 1349, in run_step\n\n  File \"/Users/pier/Projects/neural_networks/.venv/lib/python3.11/site-packages/keras/src/engine/training.py\", line 1130, in train_step\n\n  File \"/Users/pier/Projects/neural_networks/.venv/lib/python3.11/site-packages/keras/src/optimizers/legacy/optimizer_v2.py\", line 598, in minimize\n\n  File \"/Users/pier/Projects/neural_networks/.venv/lib/python3.11/site-packages/keras/src/optimizers/legacy/optimizer_v2.py\", line 656, in _compute_gradients\n\n  File \"/Users/pier/Projects/neural_networks/.venv/lib/python3.11/site-packages/keras/src/optimizers/legacy/optimizer_v2.py\", line 532, in _get_gradients\n\nIncompatible shapes: [64,500,3,12] vs. [64,12]\n\t [[{{node gradient_tape/mean_squared_error/BroadcastGradientArgs}}]] [Op:__inference_train_function_9080]\n"
}