{
    "error_message": "Graph execution error:\n\nDetected at node sub_1 defined at (most recent call last):\n  File \"/Users/pier/Projects/neural_networks/src/main.py\", line 161, in <module>\n\n  File \"/Users/pier/Projects/neural_networks/src/main.py\", line 148, in main\n\n  File \"/Users/pier/Projects/neural_networks/src/main.py\", line 98, in process_configuration\n\n  File \"/Users/pier/Projects/neural_networks/src/deepnn/model.py\", line 138, in train_model\n\n  File \"/Users/pier/Projects/neural_networks/.venv/lib/python3.11/site-packages/keras/src/utils/traceback_utils.py\", line 65, in error_handler\n\n  File \"/Users/pier/Projects/neural_networks/.venv/lib/python3.11/site-packages/keras/src/engine/training.py\", line 1783, in fit\n\n  File \"/Users/pier/Projects/neural_networks/.venv/lib/python3.11/site-packages/keras/src/engine/training.py\", line 1377, in train_function\n\n  File \"/Users/pier/Projects/neural_networks/.venv/lib/python3.11/site-packages/keras/src/engine/training.py\", line 1360, in step_function\n\n  File \"/Users/pier/Projects/neural_networks/.venv/lib/python3.11/site-packages/keras/src/engine/training.py\", line 1349, in run_step\n\n  File \"/Users/pier/Projects/neural_networks/.venv/lib/python3.11/site-packages/keras/src/engine/training.py\", line 1131, in train_step\n\n  File \"/Users/pier/Projects/neural_networks/.venv/lib/python3.11/site-packages/keras/src/engine/training.py\", line 1225, in compute_metrics\n\n  File \"/Users/pier/Projects/neural_networks/.venv/lib/python3.11/site-packages/keras/src/engine/compile_utils.py\", line 620, in update_state\n\n  File \"/Users/pier/Projects/neural_networks/.venv/lib/python3.11/site-packages/keras/src/utils/metrics_utils.py\", line 77, in decorated\n\n  File \"/Users/pier/Projects/neural_networks/.venv/lib/python3.11/site-packages/keras/src/metrics/base_metric.py\", line 140, in update_state_fn\n\n  File \"/Users/pier/Projects/neural_networks/.venv/lib/python3.11/site-packages/keras/src/metrics/base_metric.py\", line 723, in update_state\n\n  File \"/Users/pier/Projects/neural_networks/.venv/lib/python3.11/site-packages/keras/src/losses.py\", line 1893, in mean_absolute_percentage_error\n\nIncompatible shapes: [64,12] vs. [64,500,3,12]\n\t [[{{node sub_1}}]] [Op:__inference_train_function_224172]",
    "traceback": "Traceback (most recent call last):\n  File \"/Users/pier/Projects/neural_networks/src/main.py\", line 98, in process_configuration\n    history = neural_network.train_model()\n              ^^^^^^^^^^^^^^^^^^^^^^^^^^^^\n  File \"/Users/pier/Projects/neural_networks/src/deepnn/model.py\", line 138, in train_model\n    history = self.model.fit(\n              ^^^^^^^^^^^^^^^\n  File \"/Users/pier/Projects/neural_networks/.venv/lib/python3.11/site-packages/keras/src/utils/traceback_utils.py\", line 70, in error_handler\n    raise e.with_traceback(filtered_tb) from None\n  File \"/Users/pier/Projects/neural_networks/.venv/lib/python3.11/site-packages/tensorflow/python/eager/execute.py\", line 66, in quick_execute\n    except TypeError as e:\ntensorflow.python.framework.errors_impl.InvalidArgumentError: Graph execution error:\n\nDetected at node sub_1 defined at (most recent call last):\n  File \"/Users/pier/Projects/neural_networks/src/main.py\", line 161, in <module>\n\n  File \"/Users/pier/Projects/neural_networks/src/main.py\", line 148, in main\n\n  File \"/Users/pier/Projects/neural_networks/src/main.py\", line 98, in process_configuration\n\n  File \"/Users/pier/Projects/neural_networks/src/deepnn/model.py\", line 138, in train_model\n\n  File \"/Users/pier/Projects/neural_networks/.venv/lib/python3.11/site-packages/keras/src/utils/traceback_utils.py\", line 65, in error_handler\n\n  File \"/Users/pier/Projects/neural_networks/.venv/lib/python3.11/site-packages/keras/src/engine/training.py\", line 1783, in fit\n\n  File \"/Users/pier/Projects/neural_networks/.venv/lib/python3.11/site-packages/keras/src/engine/training.py\", line 1377, in train_function\n\n  File \"/Users/pier/Projects/neural_networks/.venv/lib/python3.11/site-packages/keras/src/engine/training.py\", line 1360, in step_function\n\n  File \"/Users/pier/Projects/neural_networks/.venv/lib/python3.11/site-packages/keras/src/engine/training.py\", line 1349, in run_step\n\n  File \"/Users/pier/Projects/neural_networks/.venv/lib/python3.11/site-packages/keras/src/engine/training.py\", line 1131, in train_step\n\n  File \"/Users/pier/Projects/neural_networks/.venv/lib/python3.11/site-packages/keras/src/engine/training.py\", line 1225, in compute_metrics\n\n  File \"/Users/pier/Projects/neural_networks/.venv/lib/python3.11/site-packages/keras/src/engine/compile_utils.py\", line 620, in update_state\n\n  File \"/Users/pier/Projects/neural_networks/.venv/lib/python3.11/site-packages/keras/src/utils/metrics_utils.py\", line 77, in decorated\n\n  File \"/Users/pier/Projects/neural_networks/.venv/lib/python3.11/site-packages/keras/src/metrics/base_metric.py\", line 140, in update_state_fn\n\n  File \"/Users/pier/Projects/neural_networks/.venv/lib/python3.11/site-packages/keras/src/metrics/base_metric.py\", line 723, in update_state\n\n  File \"/Users/pier/Projects/neural_networks/.venv/lib/python3.11/site-packages/keras/src/losses.py\", line 1893, in mean_absolute_percentage_error\n\nIncompatible shapes: [64,12] vs. [64,500,3,12]\n\t [[{{node sub_1}}]] [Op:__inference_train_function_224172]\n"
}